[2024-03-18T06:41:53.982+0000] {taskinstance.py:1979} INFO - Dependencies all met for dep_context=non-requeueable deps ti=<TaskInstance: two_separate_groups.local_to_gcs_4_task manual__2024-03-18T06:40:31.356042+00:00 [queued]>
[2024-03-18T06:41:54.060+0000] {taskinstance.py:1979} INFO - Dependencies all met for dep_context=requeueable deps ti=<TaskInstance: two_separate_groups.local_to_gcs_4_task manual__2024-03-18T06:40:31.356042+00:00 [queued]>
[2024-03-18T06:41:54.062+0000] {taskinstance.py:2193} INFO - Starting attempt 1 of 1
[2024-03-18T06:41:54.153+0000] {taskinstance.py:2214} INFO - Executing <Task(PythonOperator): local_to_gcs_4_task> on 2024-03-18 06:40:31.356042+00:00
[2024-03-18T06:41:54.179+0000] {standard_task_runner.py:60} INFO - Started process 352 to run task
[2024-03-18T06:41:54.201+0000] {standard_task_runner.py:87} INFO - Running: ['***', 'tasks', 'run', 'two_separate_groups', 'local_to_gcs_4_task', 'manual__2024-03-18T06:40:31.356042+00:00', '--job-id', '235', '--raw', '--subdir', 'DAGS_FOLDER/ingest_data_to_gcs.py', '--cfg-path', '/tmp/tmpyjm4yxg5']
[2024-03-18T06:41:54.207+0000] {standard_task_runner.py:88} INFO - Job 235: Subtask local_to_gcs_4_task
[2024-03-18T06:41:54.421+0000] {task_command.py:423} INFO - Running <TaskInstance: two_separate_groups.local_to_gcs_4_task manual__2024-03-18T06:40:31.356042+00:00 [running]> on host 9958f290dc4a
[2024-03-18T06:41:54.650+0000] {taskinstance.py:2510} INFO - Exporting env vars: AIRFLOW_CTX_DAG_OWNER='***' AIRFLOW_CTX_DAG_ID='two_separate_groups' AIRFLOW_CTX_TASK_ID='local_to_gcs_4_task' AIRFLOW_CTX_EXECUTION_DATE='2024-03-18T06:40:31.356042+00:00' AIRFLOW_CTX_TRY_NUMBER='1' AIRFLOW_CTX_DAG_RUN_ID='manual__2024-03-18T06:40:31.356042+00:00'
[2024-03-18T06:41:54.794+0000] {taskinstance.py:2728} ERROR - Task failed with exception
Traceback (most recent call last):
  File "/home/airflow/.local/lib/python3.8/site-packages/airflow/models/taskinstance.py", line 444, in _execute_task
    result = _execute_callable(context=context, **execute_callable_kwargs)
  File "/home/airflow/.local/lib/python3.8/site-packages/airflow/models/taskinstance.py", line 414, in _execute_callable
    return execute_callable(context=context, **execute_callable_kwargs)
  File "/home/airflow/.local/lib/python3.8/site-packages/airflow/operators/python.py", line 200, in execute
    return_value = self.execute_callable()
  File "/home/airflow/.local/lib/python3.8/site-packages/airflow/operators/python.py", line 217, in execute_callable
    return self.python_callable(*self.op_args, **self.op_kwargs)
  File "/opt/airflow/dags/ingest_data_to_gcs.py", line 59, in upload_to_gcs
    blob.upload_from_filename(local_file)
  File "/home/airflow/.local/lib/python3.8/site-packages/google/cloud/storage/blob.py", line 2929, in upload_from_filename
    self._handle_filename_and_upload(
  File "/home/airflow/.local/lib/python3.8/site-packages/google/cloud/storage/blob.py", line 2797, in _handle_filename_and_upload
    with open(filename, "rb") as file_obj:
FileNotFoundError: [Errno 2] No such file or directory: '/opt/airflow/chicago_crime_data_4.parquet'
[2024-03-18T06:41:54.811+0000] {taskinstance.py:1149} INFO - Marking task as FAILED. dag_id=two_separate_groups, task_id=local_to_gcs_4_task, execution_date=20240318T064031, start_date=20240318T064153, end_date=20240318T064154
[2024-03-18T06:41:54.835+0000] {standard_task_runner.py:107} ERROR - Failed to execute job 235 for task local_to_gcs_4_task ([Errno 2] No such file or directory: '/opt/airflow/chicago_crime_data_4.parquet'; 352)
[2024-03-18T06:41:54.888+0000] {local_task_job_runner.py:234} INFO - Task exited with return code 1
[2024-03-18T06:41:54.917+0000] {taskinstance.py:3309} INFO - 0 downstream tasks scheduled from follow-on schedule check
