[2024-03-18T06:41:23.854+0000] {taskinstance.py:1979} INFO - Dependencies all met for dep_context=non-requeueable deps ti=<TaskInstance: two_separate_groups.local_to_gcs_4_task scheduled__2024-03-17T00:00:00+00:00 [queued]>
[2024-03-18T06:41:24.036+0000] {taskinstance.py:1979} INFO - Dependencies all met for dep_context=requeueable deps ti=<TaskInstance: two_separate_groups.local_to_gcs_4_task scheduled__2024-03-17T00:00:00+00:00 [queued]>
[2024-03-18T06:41:24.041+0000] {taskinstance.py:2193} INFO - Starting attempt 1 of 1
[2024-03-18T06:41:24.170+0000] {taskinstance.py:2214} INFO - Executing <Task(PythonOperator): local_to_gcs_4_task> on 2024-03-17 00:00:00+00:00
[2024-03-18T06:41:24.178+0000] {standard_task_runner.py:60} INFO - Started process 275 to run task
[2024-03-18T06:41:24.257+0000] {standard_task_runner.py:87} INFO - Running: ['***', 'tasks', 'run', 'two_separate_groups', 'local_to_gcs_4_task', 'scheduled__2024-03-17T00:00:00+00:00', '--job-id', '214', '--raw', '--subdir', 'DAGS_FOLDER/ingest_data_to_gcs.py', '--cfg-path', '/tmp/tmpaxw5f0i8']
[2024-03-18T06:41:24.270+0000] {standard_task_runner.py:88} INFO - Job 214: Subtask local_to_gcs_4_task
[2024-03-18T06:41:24.458+0000] {task_command.py:423} INFO - Running <TaskInstance: two_separate_groups.local_to_gcs_4_task scheduled__2024-03-17T00:00:00+00:00 [running]> on host 9958f290dc4a
[2024-03-18T06:41:24.969+0000] {taskinstance.py:2510} INFO - Exporting env vars: AIRFLOW_CTX_DAG_OWNER='***' AIRFLOW_CTX_DAG_ID='two_separate_groups' AIRFLOW_CTX_TASK_ID='local_to_gcs_4_task' AIRFLOW_CTX_EXECUTION_DATE='2024-03-17T00:00:00+00:00' AIRFLOW_CTX_TRY_NUMBER='1' AIRFLOW_CTX_DAG_RUN_ID='scheduled__2024-03-17T00:00:00+00:00'
[2024-03-18T06:41:25.775+0000] {taskinstance.py:2728} ERROR - Task failed with exception
Traceback (most recent call last):
  File "/home/airflow/.local/lib/python3.8/site-packages/airflow/models/taskinstance.py", line 444, in _execute_task
    result = _execute_callable(context=context, **execute_callable_kwargs)
  File "/home/airflow/.local/lib/python3.8/site-packages/airflow/models/taskinstance.py", line 414, in _execute_callable
    return execute_callable(context=context, **execute_callable_kwargs)
  File "/home/airflow/.local/lib/python3.8/site-packages/airflow/operators/python.py", line 200, in execute
    return_value = self.execute_callable()
  File "/home/airflow/.local/lib/python3.8/site-packages/airflow/operators/python.py", line 217, in execute_callable
    return self.python_callable(*self.op_args, **self.op_kwargs)
  File "/opt/airflow/dags/ingest_data_to_gcs.py", line 59, in upload_to_gcs
    blob.upload_from_filename(local_file)
  File "/home/airflow/.local/lib/python3.8/site-packages/google/cloud/storage/blob.py", line 2929, in upload_from_filename
    self._handle_filename_and_upload(
  File "/home/airflow/.local/lib/python3.8/site-packages/google/cloud/storage/blob.py", line 2797, in _handle_filename_and_upload
    with open(filename, "rb") as file_obj:
FileNotFoundError: [Errno 2] No such file or directory: '/opt/airflow/chicago_crime_data_4.parquet'
[2024-03-18T06:41:25.867+0000] {taskinstance.py:1149} INFO - Marking task as FAILED. dag_id=two_separate_groups, task_id=local_to_gcs_4_task, execution_date=20240317T000000, start_date=20240318T064123, end_date=20240318T064125
[2024-03-18T06:41:25.977+0000] {standard_task_runner.py:107} ERROR - Failed to execute job 214 for task local_to_gcs_4_task ([Errno 2] No such file or directory: '/opt/airflow/chicago_crime_data_4.parquet'; 275)
[2024-03-18T06:41:26.066+0000] {local_task_job_runner.py:234} INFO - Task exited with return code 1
[2024-03-18T06:41:26.134+0000] {taskinstance.py:3309} INFO - 0 downstream tasks scheduled from follow-on schedule check
