[2024-03-30T09:46:37.417+0000] {taskinstance.py:1979} INFO - Dependencies all met for dep_context=non-requeueable deps ti=<TaskInstance: data_crime_process_dag.create_dataproc_cluster manual__2024-03-29T11:33:06.238124+00:00 [queued]>
[2024-03-30T09:46:37.426+0000] {taskinstance.py:1979} INFO - Dependencies all met for dep_context=requeueable deps ti=<TaskInstance: data_crime_process_dag.create_dataproc_cluster manual__2024-03-29T11:33:06.238124+00:00 [queued]>
[2024-03-30T09:46:37.426+0000] {taskinstance.py:2193} INFO - Starting attempt 4 of 5
[2024-03-30T09:46:37.439+0000] {taskinstance.py:2214} INFO - Executing <Task(DataprocCreateClusterOperator): create_dataproc_cluster> on 2024-03-29 11:33:06.238124+00:00
[2024-03-30T09:46:37.444+0000] {standard_task_runner.py:60} INFO - Started process 567 to run task
[2024-03-30T09:46:37.446+0000] {standard_task_runner.py:87} INFO - Running: ['***', 'tasks', 'run', 'data_crime_process_dag', 'create_dataproc_cluster', 'manual__2024-03-29T11:33:06.238124+00:00', '--job-id', '548', '--raw', '--subdir', 'DAGS_FOLDER/data_transformation.py', '--cfg-path', '/tmp/tmp28zkl84b']
[2024-03-30T09:46:37.448+0000] {standard_task_runner.py:88} INFO - Job 548: Subtask create_dataproc_cluster
[2024-03-30T09:46:37.487+0000] {task_command.py:423} INFO - Running <TaskInstance: data_crime_process_dag.create_dataproc_cluster manual__2024-03-29T11:33:06.238124+00:00 [running]> on host 0f6b1d3e95d8
[2024-03-30T09:46:37.563+0000] {taskinstance.py:2510} INFO - Exporting env vars: AIRFLOW_CTX_DAG_OWNER='***' AIRFLOW_CTX_DAG_ID='data_crime_process_dag' AIRFLOW_CTX_TASK_ID='create_dataproc_cluster' AIRFLOW_CTX_EXECUTION_DATE='2024-03-29T11:33:06.238124+00:00' AIRFLOW_CTX_TRY_NUMBER='4' AIRFLOW_CTX_DAG_RUN_ID='manual__2024-03-29T11:33:06.238124+00:00'
[2024-03-30T09:46:37.564+0000] {dataproc.py:778} INFO - Creating cluster: dataproc-cluster
[2024-03-30T09:46:37.566+0000] {crypto.py:82} WARNING - empty cryptography key - values will not be stored encrypted.
[2024-03-30T09:46:37.566+0000] {connection.py:269} WARNING - Connection schemes (type: google_cloud_platform) shall not contain '_' according to RFC3986.
[2024-03-30T09:46:37.567+0000] {base.py:83} INFO - Using connection ID 'google_cloud_default' for task execution.
[2024-03-30T09:46:37.632+0000] {taskinstance.py:2728} ERROR - Task failed with exception
Traceback (most recent call last):
  File "/home/airflow/.local/lib/python3.8/site-packages/proto/message.py", line 581, in __init__
    pb_value = marshal.to_proto(pb_type, value)
  File "/home/airflow/.local/lib/python3.8/site-packages/proto/marshal/marshal.py", line 228, in to_proto
    pb_value = self.get_rule(proto_type=proto_type).to_proto(value)
  File "/home/airflow/.local/lib/python3.8/site-packages/proto/marshal/rules/message.py", line 36, in to_proto
    return self._descriptor(**value)
ValueError: unknown enum label "R"

During handling of the above exception, another exception occurred:

Traceback (most recent call last):
  File "/home/airflow/.local/lib/python3.8/site-packages/airflow/models/taskinstance.py", line 444, in _execute_task
    result = _execute_callable(context=context, **execute_callable_kwargs)
  File "/home/airflow/.local/lib/python3.8/site-packages/airflow/models/taskinstance.py", line 414, in _execute_callable
    return execute_callable(context=context, **execute_callable_kwargs)
  File "/home/airflow/.local/lib/python3.8/site-packages/airflow/providers/google/cloud/operators/dataproc.py", line 794, in execute
    operation = self._create_cluster(hook)
  File "/home/airflow/.local/lib/python3.8/site-packages/airflow/providers/google/cloud/operators/dataproc.py", line 694, in _create_cluster
    return hook.create_cluster(
  File "/home/airflow/.local/lib/python3.8/site-packages/airflow/providers/google/common/hooks/base_google.py", line 485, in inner_wrapper
    return func(self, *args, **kwargs)
  File "/home/airflow/.local/lib/python3.8/site-packages/airflow/providers/google/cloud/hooks/dataproc.py", line 327, in create_cluster
    result = client.create_cluster(
  File "/home/airflow/.local/lib/python3.8/site-packages/google/cloud/dataproc_v1/services/cluster_controller/client.py", line 828, in create_cluster
    request = clusters.CreateClusterRequest(request)
  File "/home/airflow/.local/lib/python3.8/site-packages/proto/message.py", line 609, in __init__
    pb_value = marshal.to_proto(pb_type, value)
  File "/home/airflow/.local/lib/python3.8/site-packages/proto/marshal/marshal.py", line 228, in to_proto
    pb_value = self.get_rule(proto_type=proto_type).to_proto(value)
  File "/home/airflow/.local/lib/python3.8/site-packages/proto/marshal/rules/message.py", line 36, in to_proto
    return self._descriptor(**value)
ValueError: unknown enum label "R"
[2024-03-30T09:46:37.693+0000] {taskinstance.py:1149} INFO - Marking task as UP_FOR_RETRY. dag_id=data_crime_process_dag, task_id=create_dataproc_cluster, execution_date=20240329T113306, start_date=20240330T094637, end_date=20240330T094637
[2024-03-30T09:46:37.710+0000] {standard_task_runner.py:107} ERROR - Failed to execute job 548 for task create_dataproc_cluster (unknown enum label "R"; 567)
[2024-03-30T09:46:37.739+0000] {local_task_job_runner.py:234} INFO - Task exited with return code 1
[2024-03-30T09:46:37.755+0000] {taskinstance.py:3309} INFO - 0 downstream tasks scheduled from follow-on schedule check
