[2024-03-18T06:41:26.804+0000] {taskinstance.py:1979} INFO - Dependencies all met for dep_context=non-requeueable deps ti=<TaskInstance: two_separate_groups.format_to_parquet_dataset_0_task manual__2024-03-18T06:40:31.356042+00:00 [queued]>
[2024-03-18T06:41:27.015+0000] {taskinstance.py:1979} INFO - Dependencies all met for dep_context=requeueable deps ti=<TaskInstance: two_separate_groups.format_to_parquet_dataset_0_task manual__2024-03-18T06:40:31.356042+00:00 [queued]>
[2024-03-18T06:41:27.022+0000] {taskinstance.py:2193} INFO - Starting attempt 1 of 1
[2024-03-18T06:41:27.311+0000] {taskinstance.py:2214} INFO - Executing <Task(PythonOperator): format_to_parquet_dataset_0_task> on 2024-03-18 06:40:31.356042+00:00
[2024-03-18T06:41:27.378+0000] {standard_task_runner.py:60} INFO - Started process 283 to run task
[2024-03-18T06:41:27.436+0000] {standard_task_runner.py:87} INFO - Running: ['***', 'tasks', 'run', 'two_separate_groups', 'format_to_parquet_dataset_0_task', 'manual__2024-03-18T06:40:31.356042+00:00', '--job-id', '216', '--raw', '--subdir', 'DAGS_FOLDER/ingest_data_to_gcs.py', '--cfg-path', '/tmp/tmpsqn4y9nf']
[2024-03-18T06:41:27.486+0000] {standard_task_runner.py:88} INFO - Job 216: Subtask format_to_parquet_dataset_0_task
[2024-03-18T06:41:27.806+0000] {task_command.py:423} INFO - Running <TaskInstance: two_separate_groups.format_to_parquet_dataset_0_task manual__2024-03-18T06:40:31.356042+00:00 [running]> on host 9958f290dc4a
[2024-03-18T06:41:29.243+0000] {taskinstance.py:2510} INFO - Exporting env vars: AIRFLOW_CTX_DAG_OWNER='***' AIRFLOW_CTX_DAG_ID='two_separate_groups' AIRFLOW_CTX_TASK_ID='format_to_parquet_dataset_0_task' AIRFLOW_CTX_EXECUTION_DATE='2024-03-18T06:40:31.356042+00:00' AIRFLOW_CTX_TRY_NUMBER='1' AIRFLOW_CTX_DAG_RUN_ID='manual__2024-03-18T06:40:31.356042+00:00'
[2024-03-18T06:41:30.075+0000] {taskinstance.py:2728} ERROR - Task failed with exception
Traceback (most recent call last):
  File "/home/airflow/.local/lib/python3.8/site-packages/airflow/models/taskinstance.py", line 444, in _execute_task
    result = _execute_callable(context=context, **execute_callable_kwargs)
  File "/home/airflow/.local/lib/python3.8/site-packages/airflow/models/taskinstance.py", line 414, in _execute_callable
    return execute_callable(context=context, **execute_callable_kwargs)
  File "/home/airflow/.local/lib/python3.8/site-packages/airflow/operators/python.py", line 200, in execute
    return_value = self.execute_callable()
  File "/home/airflow/.local/lib/python3.8/site-packages/airflow/operators/python.py", line 217, in execute_callable
    return self.python_callable(*self.op_args, **self.op_kwargs)
  File "/opt/airflow/dags/ingest_data_to_gcs.py", line 38, in format_to_parquet
    table = pv.read_csv(src_file)
  File "pyarrow/_csv.pyx", line 1261, in pyarrow._csv.read_csv
  File "pyarrow/_csv.pyx", line 1270, in pyarrow._csv.read_csv
  File "pyarrow/error.pxi", line 154, in pyarrow.lib.pyarrow_internal_check_status
  File "pyarrow/error.pxi", line 91, in pyarrow.lib.check_status
pyarrow.lib.ArrowInvalid: CSV parse error: Expected 30 columns, got 14: 10678659,HZ431547,09/12/2016 05:30:00 AM,031XX S UNION AVE,0486,BATTERY,DOMESTIC BATTERY SIMPLE, ...
[2024-03-18T06:41:30.123+0000] {taskinstance.py:1149} INFO - Marking task as FAILED. dag_id=two_separate_groups, task_id=format_to_parquet_dataset_0_task, execution_date=20240318T064031, start_date=20240318T064126, end_date=20240318T064130
[2024-03-18T06:41:30.177+0000] {standard_task_runner.py:107} ERROR - Failed to execute job 216 for task format_to_parquet_dataset_0_task (CSV parse error: Expected 30 columns, got 14: 10678659,HZ431547,09/12/2016 05:30:00 AM,031XX S UNION AVE,0486,BATTERY,DOMESTIC BATTERY SIMPLE, ...; 283)
[2024-03-18T06:41:30.337+0000] {local_task_job_runner.py:234} INFO - Task exited with return code 1
[2024-03-18T06:41:30.607+0000] {taskinstance.py:3309} INFO - 0 downstream tasks scheduled from follow-on schedule check
