[2024-03-12T13:35:10.123+0000] {taskinstance.py:1979} INFO - Dependencies all met for dep_context=non-requeueable deps ti=<TaskInstance: two_separate_groups.local_to_gcs_1_task manual__2024-03-12T12:13:33.995482+00:00 [queued]>
[2024-03-12T13:35:10.149+0000] {taskinstance.py:1979} INFO - Dependencies all met for dep_context=requeueable deps ti=<TaskInstance: two_separate_groups.local_to_gcs_1_task manual__2024-03-12T12:13:33.995482+00:00 [queued]>
[2024-03-12T13:35:10.150+0000] {taskinstance.py:2193} INFO - Starting attempt 1 of 1
[2024-03-12T13:35:10.181+0000] {taskinstance.py:2214} INFO - Executing <Task(PythonOperator): local_to_gcs_1_task> on 2024-03-12 12:13:33.995482+00:00
[2024-03-12T13:35:10.188+0000] {standard_task_runner.py:60} INFO - Started process 3547 to run task
[2024-03-12T13:35:10.212+0000] {standard_task_runner.py:87} INFO - Running: ['***', 'tasks', 'run', 'two_separate_groups', 'local_to_gcs_1_task', 'manual__2024-03-12T12:13:33.995482+00:00', '--job-id', '99', '--raw', '--subdir', 'DAGS_FOLDER/create_dag.py', '--cfg-path', '/tmp/tmpuwdhzdq9']
[2024-03-12T13:35:10.213+0000] {standard_task_runner.py:88} INFO - Job 99: Subtask local_to_gcs_1_task
[2024-03-12T13:35:10.367+0000] {task_command.py:423} INFO - Running <TaskInstance: two_separate_groups.local_to_gcs_1_task manual__2024-03-12T12:13:33.995482+00:00 [running]> on host 9958f290dc4a
[2024-03-12T13:35:10.573+0000] {taskinstance.py:2510} INFO - Exporting env vars: AIRFLOW_CTX_DAG_OWNER='***' AIRFLOW_CTX_DAG_ID='two_separate_groups' AIRFLOW_CTX_TASK_ID='local_to_gcs_1_task' AIRFLOW_CTX_EXECUTION_DATE='2024-03-12T12:13:33.995482+00:00' AIRFLOW_CTX_TRY_NUMBER='1' AIRFLOW_CTX_DAG_RUN_ID='manual__2024-03-12T12:13:33.995482+00:00'
[2024-03-12T13:35:10.727+0000] {taskinstance.py:2728} ERROR - Task failed with exception
Traceback (most recent call last):
  File "/home/airflow/.local/lib/python3.8/site-packages/airflow/models/taskinstance.py", line 444, in _execute_task
    result = _execute_callable(context=context, **execute_callable_kwargs)
  File "/home/airflow/.local/lib/python3.8/site-packages/airflow/models/taskinstance.py", line 414, in _execute_callable
    return execute_callable(context=context, **execute_callable_kwargs)
  File "/home/airflow/.local/lib/python3.8/site-packages/airflow/operators/python.py", line 200, in execute
    return_value = self.execute_callable()
  File "/home/airflow/.local/lib/python3.8/site-packages/airflow/operators/python.py", line 217, in execute_callable
    return self.python_callable(*self.op_args, **self.op_kwargs)
  File "/opt/airflow/dags/create_dag.py", line 58, in upload_to_gcs
    blob.upload_from_filename(local_file)
  File "/home/airflow/.local/lib/python3.8/site-packages/google/cloud/storage/blob.py", line 2929, in upload_from_filename
    self._handle_filename_and_upload(
  File "/home/airflow/.local/lib/python3.8/site-packages/google/cloud/storage/blob.py", line 2797, in _handle_filename_and_upload
    with open(filename, "rb") as file_obj:
FileNotFoundError: [Errno 2] No such file or directory: '/opt/airflow/chicago_crime_data_1.parquet'
[2024-03-12T13:35:10.740+0000] {taskinstance.py:1149} INFO - Marking task as FAILED. dag_id=two_separate_groups, task_id=local_to_gcs_1_task, execution_date=20240312T121333, start_date=20240312T133510, end_date=20240312T133510
[2024-03-12T13:35:10.763+0000] {standard_task_runner.py:107} ERROR - Failed to execute job 99 for task local_to_gcs_1_task ([Errno 2] No such file or directory: '/opt/airflow/chicago_crime_data_1.parquet'; 3547)
[2024-03-12T13:35:10.785+0000] {local_task_job_runner.py:234} INFO - Task exited with return code 1
[2024-03-12T13:35:10.847+0000] {taskinstance.py:3309} INFO - 0 downstream tasks scheduled from follow-on schedule check
