[2024-03-31T06:12:40.674+0000] {taskinstance.py:1979} INFO - Dependencies all met for dep_context=non-requeueable deps ti=<TaskInstance: ingesting_data_bq.local_to_gcs_4_task scheduled__2024-03-28T00:00:00+00:00 [queued]>
[2024-03-31T06:12:41.040+0000] {taskinstance.py:1979} INFO - Dependencies all met for dep_context=requeueable deps ti=<TaskInstance: ingesting_data_bq.local_to_gcs_4_task scheduled__2024-03-28T00:00:00+00:00 [queued]>
[2024-03-31T06:12:41.045+0000] {taskinstance.py:2193} INFO - Starting attempt 1 of 1
[2024-03-31T06:12:41.311+0000] {taskinstance.py:2214} INFO - Executing <Task(PythonOperator): local_to_gcs_4_task> on 2024-03-28 00:00:00+00:00
[2024-03-31T06:12:41.345+0000] {standard_task_runner.py:60} INFO - Started process 305 to run task
[2024-03-31T06:12:41.351+0000] {standard_task_runner.py:87} INFO - Running: ['***', 'tasks', 'run', 'ingesting_data_bq', 'local_to_gcs_4_task', 'scheduled__2024-03-28T00:00:00+00:00', '--job-id', '564', '--raw', '--subdir', 'DAGS_FOLDER/ingest_data_to_gcs.py', '--cfg-path', '/tmp/tmp2fz6we_t']
[2024-03-31T06:12:41.353+0000] {standard_task_runner.py:88} INFO - Job 564: Subtask local_to_gcs_4_task
[2024-03-31T06:12:42.864+0000] {task_command.py:423} INFO - Running <TaskInstance: ingesting_data_bq.local_to_gcs_4_task scheduled__2024-03-28T00:00:00+00:00 [running]> on host 0f6b1d3e95d8
[2024-03-31T06:12:54.689+0000] {taskinstance.py:2510} INFO - Exporting env vars: AIRFLOW_CTX_DAG_OWNER='***' AIRFLOW_CTX_DAG_ID='ingesting_data_bq' AIRFLOW_CTX_TASK_ID='local_to_gcs_4_task' AIRFLOW_CTX_EXECUTION_DATE='2024-03-28T00:00:00+00:00' AIRFLOW_CTX_TRY_NUMBER='1' AIRFLOW_CTX_DAG_RUN_ID='scheduled__2024-03-28T00:00:00+00:00'
[2024-03-31T06:13:04.647+0000] {connectionpool.py:824} WARNING - Retrying (Retry(total=2, connect=None, read=None, redirect=None, status=None)) after connection broken by 'NewConnectionError('<urllib3.connection.HTTPSConnection object at 0x7f26b49561f0>: Failed to establish a new connection: [Errno -3] Temporary failure in name resolution')': /token
[2024-03-31T06:13:12.659+0000] {connectionpool.py:824} WARNING - Retrying (Retry(total=1, connect=None, read=None, redirect=None, status=None)) after connection broken by 'NewConnectionError('<urllib3.connection.HTTPSConnection object at 0x7f26b4956340>: Failed to establish a new connection: [Errno -3] Temporary failure in name resolution')': /token
[2024-03-31T06:13:14.327+0000] {python.py:202} INFO - Done. Returned value was: None
[2024-03-31T06:13:14.345+0000] {taskinstance.py:1149} INFO - Marking task as SUCCESS. dag_id=ingesting_data_bq, task_id=local_to_gcs_4_task, execution_date=20240328T000000, start_date=20240331T061240, end_date=20240331T061314
[2024-03-31T06:13:14.406+0000] {local_task_job_runner.py:234} INFO - Task exited with return code 0
[2024-03-31T06:13:14.453+0000] {taskinstance.py:3309} INFO - 1 downstream tasks scheduled from follow-on schedule check
