[2024-03-26T15:38:53.965+0000] {taskinstance.py:1979} INFO - Dependencies all met for dep_context=non-requeueable deps ti=<TaskInstance: data_crime_process_dag.create_dataproc_cluster manual__2024-03-26T08:20:00.691315+00:00 [queued]>
[2024-03-26T15:38:53.978+0000] {taskinstance.py:1979} INFO - Dependencies all met for dep_context=requeueable deps ti=<TaskInstance: data_crime_process_dag.create_dataproc_cluster manual__2024-03-26T08:20:00.691315+00:00 [queued]>
[2024-03-26T15:38:53.979+0000] {taskinstance.py:2193} INFO - Starting attempt 20 of 20
[2024-03-26T15:38:53.996+0000] {taskinstance.py:2214} INFO - Executing <Task(DataprocCreateClusterOperator): create_dataproc_cluster> on 2024-03-26 08:20:00.691315+00:00
[2024-03-26T15:38:54.002+0000] {standard_task_runner.py:60} INFO - Started process 1311 to run task
[2024-03-26T15:38:54.006+0000] {standard_task_runner.py:87} INFO - Running: ['***', 'tasks', 'run', 'data_crime_process_dag', 'create_dataproc_cluster', 'manual__2024-03-26T08:20:00.691315+00:00', '--job-id', '367', '--raw', '--subdir', 'DAGS_FOLDER/data_transformation.py', '--cfg-path', '/tmp/tmpajfpwgbl']
[2024-03-26T15:38:54.009+0000] {standard_task_runner.py:88} INFO - Job 367: Subtask create_dataproc_cluster
[2024-03-26T15:38:54.057+0000] {task_command.py:423} INFO - Running <TaskInstance: data_crime_process_dag.create_dataproc_cluster manual__2024-03-26T08:20:00.691315+00:00 [running]> on host d3d7fa608a49
[2024-03-26T15:38:54.138+0000] {taskinstance.py:2510} INFO - Exporting env vars: AIRFLOW_CTX_DAG_OWNER='***' AIRFLOW_CTX_DAG_ID='data_crime_process_dag' AIRFLOW_CTX_TASK_ID='create_dataproc_cluster' AIRFLOW_CTX_EXECUTION_DATE='2024-03-26T08:20:00.691315+00:00' AIRFLOW_CTX_TRY_NUMBER='20' AIRFLOW_CTX_DAG_RUN_ID='manual__2024-03-26T08:20:00.691315+00:00'
[2024-03-26T15:38:54.140+0000] {dataproc.py:778} INFO - Creating cluster: dataproc-cluster
[2024-03-26T15:38:54.142+0000] {crypto.py:82} WARNING - empty cryptography key - values will not be stored encrypted.
[2024-03-26T15:38:54.143+0000] {connection.py:269} WARNING - Connection schemes (type: google_cloud_platform) shall not contain '_' according to RFC3986.
[2024-03-26T15:38:54.144+0000] {base.py:83} INFO - Using connection ID 'google_cloud_default' for task execution.
[2024-03-26T15:38:55.460+0000] {dataproc.py:823} INFO - Cluster already exists.
[2024-03-26T15:38:55.745+0000] {dataproc.py:724} INFO - Cluster is in ERROR state
[2024-03-26T15:38:55.746+0000] {dataproc.py:725} INFO - Gathering diagnostic information.
[2024-03-26T15:38:56.219+0000] {taskinstance.py:2728} ERROR - Task failed with exception
Traceback (most recent call last):
  File "/home/airflow/.local/lib/python3.8/site-packages/airflow/models/taskinstance.py", line 444, in _execute_task
    result = _execute_callable(context=context, **execute_callable_kwargs)
  File "/home/airflow/.local/lib/python3.8/site-packages/airflow/models/taskinstance.py", line 414, in _execute_callable
    return execute_callable(context=context, **execute_callable_kwargs)
  File "/home/airflow/.local/lib/python3.8/site-packages/airflow/providers/google/cloud/operators/dataproc.py", line 843, in execute
    self._handle_error_state(hook, cluster)
  File "/home/airflow/.local/lib/python3.8/site-packages/airflow/providers/google/cloud/operators/dataproc.py", line 726, in _handle_error_state
    operation = hook.diagnose_cluster(
  File "/home/airflow/.local/lib/python3.8/site-packages/airflow/providers/google/common/hooks/base_google.py", line 485, in inner_wrapper
    return func(self, *args, **kwargs)
  File "/home/airflow/.local/lib/python3.8/site-packages/airflow/providers/google/cloud/hooks/dataproc.py", line 418, in diagnose_cluster
    result = client.diagnose_cluster(
  File "/home/airflow/.local/lib/python3.8/site-packages/google/cloud/dataproc_v1/services/cluster_controller/client.py", line 1914, in diagnose_cluster
    response = rpc(
  File "/home/airflow/.local/lib/python3.8/site-packages/google/api_core/gapic_v1/method.py", line 131, in __call__
    return wrapped_func(*args, **kwargs)
  File "/home/airflow/.local/lib/python3.8/site-packages/google/api_core/retry/retry_unary.py", line 293, in retry_wrapped_func
    return retry_target(
  File "/home/airflow/.local/lib/python3.8/site-packages/google/api_core/retry/retry_unary.py", line 153, in retry_target
    _retry_error_helper(
  File "/home/airflow/.local/lib/python3.8/site-packages/google/api_core/retry/retry_base.py", line 212, in _retry_error_helper
    raise final_exc from source_exc
  File "/home/airflow/.local/lib/python3.8/site-packages/google/api_core/retry/retry_unary.py", line 144, in retry_target
    result = target()
  File "/home/airflow/.local/lib/python3.8/site-packages/google/api_core/grpc_helpers.py", line 78, in error_remapped_callable
    raise exceptions.from_grpc_error(exc) from exc
google.api_core.exceptions.FailedPrecondition: 400 Detected missing master VMs!
Details: [Missing GCE VM dataproc-cluster-m.]
[2024-03-26T15:38:56.237+0000] {taskinstance.py:1149} INFO - Marking task as FAILED. dag_id=data_crime_process_dag, task_id=create_dataproc_cluster, execution_date=20240326T082000, start_date=20240326T153853, end_date=20240326T153856
[2024-03-26T15:38:56.257+0000] {standard_task_runner.py:107} ERROR - Failed to execute job 367 for task create_dataproc_cluster (400 Detected missing master VMs!
Details: [Missing GCE VM dataproc-cluster-m.]; 1311)
[2024-03-26T15:38:56.306+0000] {local_task_job_runner.py:234} INFO - Task exited with return code 1
[2024-03-26T15:38:56.323+0000] {taskinstance.py:3309} INFO - 0 downstream tasks scheduled from follow-on schedule check
