[2024-03-28T07:33:06.399+0000] {taskinstance.py:1979} INFO - Dependencies all met for dep_context=non-requeueable deps ti=<TaskInstance: ingesting_data_bq.format_to_parquet_dataset_0_task scheduled__2024-03-26T00:00:00+00:00 [queued]>
[2024-03-28T07:33:06.458+0000] {taskinstance.py:1979} INFO - Dependencies all met for dep_context=requeueable deps ti=<TaskInstance: ingesting_data_bq.format_to_parquet_dataset_0_task scheduled__2024-03-26T00:00:00+00:00 [queued]>
[2024-03-28T07:33:06.461+0000] {taskinstance.py:2193} INFO - Starting attempt 2 of 2
[2024-03-28T07:33:06.543+0000] {taskinstance.py:2214} INFO - Executing <Task(PythonOperator): format_to_parquet_dataset_0_task> on 2024-03-26 00:00:00+00:00
[2024-03-28T07:33:06.626+0000] {standard_task_runner.py:87} INFO - Running: ['***', 'tasks', 'run', 'ingesting_data_bq', 'format_to_parquet_dataset_0_task', 'scheduled__2024-03-26T00:00:00+00:00', '--job-id', '397', '--raw', '--subdir', 'DAGS_FOLDER/ingest_data_to_gcs.py', '--cfg-path', '/tmp/tmpjtbvucbv']
[2024-03-28T07:33:06.627+0000] {standard_task_runner.py:88} INFO - Job 397: Subtask format_to_parquet_dataset_0_task
[2024-03-28T07:33:06.566+0000] {standard_task_runner.py:60} INFO - Started process 230 to run task
[2024-03-28T07:33:07.051+0000] {task_command.py:423} INFO - Running <TaskInstance: ingesting_data_bq.format_to_parquet_dataset_0_task scheduled__2024-03-26T00:00:00+00:00 [running]> on host d3d7fa608a49
[2024-03-28T07:33:07.759+0000] {taskinstance.py:2510} INFO - Exporting env vars: AIRFLOW_CTX_DAG_OWNER='***' AIRFLOW_CTX_DAG_ID='ingesting_data_bq' AIRFLOW_CTX_TASK_ID='format_to_parquet_dataset_0_task' AIRFLOW_CTX_EXECUTION_DATE='2024-03-26T00:00:00+00:00' AIRFLOW_CTX_TRY_NUMBER='2' AIRFLOW_CTX_DAG_RUN_ID='scheduled__2024-03-26T00:00:00+00:00'
[2024-03-28T07:33:08.110+0000] {taskinstance.py:2728} ERROR - Task failed with exception
Traceback (most recent call last):
  File "/home/airflow/.local/lib/python3.8/site-packages/airflow/models/taskinstance.py", line 444, in _execute_task
    result = _execute_callable(context=context, **execute_callable_kwargs)
  File "/home/airflow/.local/lib/python3.8/site-packages/airflow/models/taskinstance.py", line 414, in _execute_callable
    return execute_callable(context=context, **execute_callable_kwargs)
  File "/home/airflow/.local/lib/python3.8/site-packages/airflow/operators/python.py", line 200, in execute
    return_value = self.execute_callable()
  File "/home/airflow/.local/lib/python3.8/site-packages/airflow/operators/python.py", line 217, in execute_callable
    return self.python_callable(*self.op_args, **self.op_kwargs)
  File "/opt/airflow/dags/ingest_data_to_gcs.py", line 37, in format_to_parquet
    table = pv.read_csv(src_file)
  File "pyarrow/_csv.pyx", line 1261, in pyarrow._csv.read_csv
  File "pyarrow/_csv.pyx", line 1270, in pyarrow._csv.read_csv
  File "pyarrow/error.pxi", line 154, in pyarrow.lib.pyarrow_internal_check_status
  File "pyarrow/error.pxi", line 91, in pyarrow.lib.check_status
pyarrow.lib.ArrowInvalid: CSV parse error: Expected 30 columns, got 22: 11101490,JA449000,08/01/2016 08:00:00 AM,077XX S RACINE AVE,1153,DECEPTIVE PRACTICE,FINANCIAL ID ...
[2024-03-28T07:33:08.121+0000] {taskinstance.py:1149} INFO - Marking task as FAILED. dag_id=ingesting_data_bq, task_id=format_to_parquet_dataset_0_task, execution_date=20240326T000000, start_date=20240328T073306, end_date=20240328T073308
[2024-03-28T07:33:08.138+0000] {standard_task_runner.py:107} ERROR - Failed to execute job 397 for task format_to_parquet_dataset_0_task (CSV parse error: Expected 30 columns, got 22: 11101490,JA449000,08/01/2016 08:00:00 AM,077XX S RACINE AVE,1153,DECEPTIVE PRACTICE,FINANCIAL ID ...; 230)
[2024-03-28T07:33:08.198+0000] {local_task_job_runner.py:234} INFO - Task exited with return code 1
[2024-03-28T07:33:08.288+0000] {taskinstance.py:3309} INFO - 0 downstream tasks scheduled from follow-on schedule check
