[2024-03-28T07:37:23.240+0000] {taskinstance.py:1979} INFO - Dependencies all met for dep_context=non-requeueable deps ti=<TaskInstance: ingesting_data_bq.local_to_gcs_CommArea_task manual__2024-03-28T07:31:49.089267+00:00 [queued]>
[2024-03-28T07:37:23.260+0000] {taskinstance.py:1979} INFO - Dependencies all met for dep_context=requeueable deps ti=<TaskInstance: ingesting_data_bq.local_to_gcs_CommArea_task manual__2024-03-28T07:31:49.089267+00:00 [queued]>
[2024-03-28T07:37:23.262+0000] {taskinstance.py:2193} INFO - Starting attempt 2 of 2
[2024-03-28T07:37:23.357+0000] {taskinstance.py:2214} INFO - Executing <Task(PythonOperator): local_to_gcs_CommArea_task> on 2024-03-28 07:31:49.089267+00:00
[2024-03-28T07:37:23.368+0000] {standard_task_runner.py:60} INFO - Started process 426 to run task
[2024-03-28T07:37:23.371+0000] {standard_task_runner.py:87} INFO - Running: ['***', 'tasks', 'run', 'ingesting_data_bq', 'local_to_gcs_CommArea_task', 'manual__2024-03-28T07:31:49.089267+00:00', '--job-id', '422', '--raw', '--subdir', 'DAGS_FOLDER/ingest_data_to_gcs.py', '--cfg-path', '/tmp/tmp4j52ejoc']
[2024-03-28T07:37:23.372+0000] {standard_task_runner.py:88} INFO - Job 422: Subtask local_to_gcs_CommArea_task
[2024-03-28T07:37:23.423+0000] {task_command.py:423} INFO - Running <TaskInstance: ingesting_data_bq.local_to_gcs_CommArea_task manual__2024-03-28T07:31:49.089267+00:00 [running]> on host d3d7fa608a49
[2024-03-28T07:37:23.519+0000] {taskinstance.py:2510} INFO - Exporting env vars: AIRFLOW_CTX_DAG_OWNER='***' AIRFLOW_CTX_DAG_ID='ingesting_data_bq' AIRFLOW_CTX_TASK_ID='local_to_gcs_CommArea_task' AIRFLOW_CTX_EXECUTION_DATE='2024-03-28T07:31:49.089267+00:00' AIRFLOW_CTX_TRY_NUMBER='2' AIRFLOW_CTX_DAG_RUN_ID='manual__2024-03-28T07:31:49.089267+00:00'
[2024-03-28T07:37:23.577+0000] {taskinstance.py:2728} ERROR - Task failed with exception
Traceback (most recent call last):
  File "/home/airflow/.local/lib/python3.8/site-packages/airflow/models/taskinstance.py", line 444, in _execute_task
    result = _execute_callable(context=context, **execute_callable_kwargs)
  File "/home/airflow/.local/lib/python3.8/site-packages/airflow/models/taskinstance.py", line 414, in _execute_callable
    return execute_callable(context=context, **execute_callable_kwargs)
  File "/home/airflow/.local/lib/python3.8/site-packages/airflow/operators/python.py", line 200, in execute
    return_value = self.execute_callable()
  File "/home/airflow/.local/lib/python3.8/site-packages/airflow/operators/python.py", line 217, in execute_callable
    return self.python_callable(*self.op_args, **self.op_kwargs)
  File "/opt/airflow/dags/ingest_data_to_gcs.py", line 58, in upload_to_gcs
    blob.upload_from_filename(local_file)
  File "/home/airflow/.local/lib/python3.8/site-packages/google/cloud/storage/blob.py", line 2929, in upload_from_filename
    self._handle_filename_and_upload(
  File "/home/airflow/.local/lib/python3.8/site-packages/google/cloud/storage/blob.py", line 2797, in _handle_filename_and_upload
    with open(filename, "rb") as file_obj:
FileNotFoundError: [Errno 2] No such file or directory: '/opt/airflow/chicago_comm_areasa.parquet'
[2024-03-28T07:37:23.590+0000] {taskinstance.py:1149} INFO - Marking task as FAILED. dag_id=ingesting_data_bq, task_id=local_to_gcs_CommArea_task, execution_date=20240328T073149, start_date=20240328T073723, end_date=20240328T073723
[2024-03-28T07:37:23.606+0000] {standard_task_runner.py:107} ERROR - Failed to execute job 422 for task local_to_gcs_CommArea_task ([Errno 2] No such file or directory: '/opt/airflow/chicago_comm_areasa.parquet'; 426)
[2024-03-28T07:37:23.665+0000] {local_task_job_runner.py:234} INFO - Task exited with return code 1
[2024-03-28T07:37:23.700+0000] {taskinstance.py:3309} INFO - 0 downstream tasks scheduled from follow-on schedule check
