[2024-04-02T13:31:29.073+0000] {taskinstance.py:1979} INFO - Dependencies all met for dep_context=non-requeueable deps ti=<TaskInstance: data_crime_process_dag.upload_pyspark_script manual__2024-03-29T11:33:06.238124+00:00 [queued]>
[2024-04-02T13:31:29.098+0000] {taskinstance.py:1979} INFO - Dependencies all met for dep_context=requeueable deps ti=<TaskInstance: data_crime_process_dag.upload_pyspark_script manual__2024-03-29T11:33:06.238124+00:00 [queued]>
[2024-04-02T13:31:29.100+0000] {taskinstance.py:2193} INFO - Starting attempt 9 of 10
[2024-04-02T13:31:29.128+0000] {taskinstance.py:2214} INFO - Executing <Task(PythonOperator): upload_pyspark_script> on 2024-03-29 11:33:06.238124+00:00
[2024-04-02T13:31:29.141+0000] {standard_task_runner.py:87} INFO - Running: ['***', 'tasks', 'run', 'data_crime_process_dag', 'upload_pyspark_script', 'manual__2024-03-29T11:33:06.238124+00:00', '--job-id', '668', '--raw', '--subdir', 'DAGS_FOLDER/data_transformation.py', '--cfg-path', '/tmp/tmpbh6y17sz']
[2024-04-02T13:31:29.146+0000] {standard_task_runner.py:88} INFO - Job 668: Subtask upload_pyspark_script
[2024-04-02T13:31:29.139+0000] {standard_task_runner.py:60} INFO - Started process 136 to run task
[2024-04-02T13:31:29.244+0000] {task_command.py:423} INFO - Running <TaskInstance: data_crime_process_dag.upload_pyspark_script manual__2024-03-29T11:33:06.238124+00:00 [running]> on host 0f6b1d3e95d8
[2024-04-02T13:31:29.373+0000] {taskinstance.py:2510} INFO - Exporting env vars: AIRFLOW_CTX_DAG_OWNER='***' AIRFLOW_CTX_DAG_ID='data_crime_process_dag' AIRFLOW_CTX_TASK_ID='upload_pyspark_script' AIRFLOW_CTX_EXECUTION_DATE='2024-03-29T11:33:06.238124+00:00' AIRFLOW_CTX_TRY_NUMBER='9' AIRFLOW_CTX_DAG_RUN_ID='manual__2024-03-29T11:33:06.238124+00:00'
[2024-04-02T13:31:29.449+0000] {taskinstance.py:2728} ERROR - Task failed with exception
Traceback (most recent call last):
  File "/home/airflow/.local/lib/python3.8/site-packages/airflow/models/taskinstance.py", line 444, in _execute_task
    result = _execute_callable(context=context, **execute_callable_kwargs)
  File "/home/airflow/.local/lib/python3.8/site-packages/airflow/models/taskinstance.py", line 414, in _execute_callable
    return execute_callable(context=context, **execute_callable_kwargs)
  File "/home/airflow/.local/lib/python3.8/site-packages/airflow/operators/python.py", line 200, in execute
    return_value = self.execute_callable()
  File "/home/airflow/.local/lib/python3.8/site-packages/airflow/operators/python.py", line 217, in execute_callable
    return self.python_callable(*self.op_args, **self.op_kwargs)
  File "/opt/airflow/dags/data_transformation.py", line 70, in upload_to_gcs
    blob.upload_from_filename(local_file)
  File "/home/airflow/.local/lib/python3.8/site-packages/google/cloud/storage/blob.py", line 2929, in upload_from_filename
    self._handle_filename_and_upload(
  File "/home/airflow/.local/lib/python3.8/site-packages/google/cloud/storage/blob.py", line 2797, in _handle_filename_and_upload
    with open(filename, "rb") as file_obj:
FileNotFoundError: [Errno 2] No such file or directory: '/opt/airflow/scripts/data_transformations.py'
[2024-04-02T13:31:29.482+0000] {taskinstance.py:1149} INFO - Marking task as UP_FOR_RETRY. dag_id=data_crime_process_dag, task_id=upload_pyspark_script, execution_date=20240329T113306, start_date=20240402T133129, end_date=20240402T133129
[2024-04-02T13:31:29.508+0000] {standard_task_runner.py:107} ERROR - Failed to execute job 668 for task upload_pyspark_script ([Errno 2] No such file or directory: '/opt/airflow/scripts/data_transformations.py'; 136)
[2024-04-02T13:31:29.544+0000] {local_task_job_runner.py:234} INFO - Task exited with return code 1
[2024-04-02T13:31:29.580+0000] {taskinstance.py:3309} INFO - 0 downstream tasks scheduled from follow-on schedule check
